2025-08-18 16:51:08,189 - ERROR - src.transfer.ftp_manager - Falha no download do ficheiro: 'utf-8' codec can't decode byte 0xe9 in position 489: invalid continuation byte
Traceback (most recent call last):
  File "d:\Python\Sage\INP\transfer-files\src\transfer\ftp_manager.py", line 122, in download_file
    self.ftp.retrlines(f'RETR {remote_path}', f.write)
  File "C:\Users\joser\.pyenv\pyenv-win\versions\3.12.7\Lib\ftplib.py", line 462, in retrlines
    line = fp.readline(self.maxline + 1)
           ^^^^^^^^^^^^^^^^^^^^^^^^^^^^^
  File "C:\Users\joser\.pyenv\pyenv-win\versions\3.12.7\Lib\codecs.py", line 322, in decode
    (result, consumed) = self._buffer_decode(data, self.errors, final)
                         ^^^^^^^^^^^^^^^^^^^^^^^^^^^^^^^^^^^^^^^^^^^^^
UnicodeDecodeError: 'utf-8' codec can't decode byte 0xe9 in position 489: invalid continuation byte
2025-08-18 16:51:08,222 - ERROR - src.services.strategies - [1510] Falha no download de R2025081401.TXT.
2025-08-18 16:51:08,317 - ERROR - src.transfer.ftp_manager - Falha inesperada ao listar ficheiros em '/Output': 200 Type set to A.
Traceback (most recent call last):
  File "d:\Python\Sage\INP\transfer-files\src\transfer\ftp_manager.py", line 71, in list_files
    return self.ftp.nlst(remote_path)
           ^^^^^^^^^^^^^^^^^^^^^^^^^^
  File "C:\Users\joser\.pyenv\pyenv-win\versions\3.12.7\Lib\ftplib.py", line 547, in nlst
    self.retrlines(cmd, files.append)
  File "C:\Users\joser\.pyenv\pyenv-win\versions\3.12.7\Lib\ftplib.py", line 459, in retrlines
    with self.transfercmd(cmd) as conn, \
         ^^^^^^^^^^^^^^^^^^^^^
  File "C:\Users\joser\.pyenv\pyenv-win\versions\3.12.7\Lib\ftplib.py", line 393, in transfercmd
    return self.ntransfercmd(cmd, rest)[0]
           ^^^^^^^^^^^^^^^^^^^^^^^^^^^^
  File "C:\Users\joser\.pyenv\pyenv-win\versions\3.12.7\Lib\ftplib.py", line 353, in ntransfercmd
    host, port = self.makepasv()
                 ^^^^^^^^^^^^^^^
  File "C:\Users\joser\.pyenv\pyenv-win\versions\3.12.7\Lib\ftplib.py", line 327, in makepasv
    untrusted_host, port = parse227(self.sendcmd('PASV'))
                           ^^^^^^^^^^^^^^^^^^^^^^^^^^^^^^
  File "C:\Users\joser\.pyenv\pyenv-win\versions\3.12.7\Lib\ftplib.py", line 817, in parse227
    raise error_reply(resp)
ftplib.error_reply: 200 Type set to A.
2025-08-18 16:51:08,412 - ERROR - src.transfer.ftp_manager - Falha inesperada ao listar ficheiros em '/Output': 200 Type set to A.
Traceback (most recent call last):
  File "d:\Python\Sage\INP\transfer-files\src\transfer\ftp_manager.py", line 71, in list_files
    return self.ftp.nlst(remote_path)
           ^^^^^^^^^^^^^^^^^^^^^^^^^^
  File "C:\Users\joser\.pyenv\pyenv-win\versions\3.12.7\Lib\ftplib.py", line 547, in nlst
    self.retrlines(cmd, files.append)
  File "C:\Users\joser\.pyenv\pyenv-win\versions\3.12.7\Lib\ftplib.py", line 459, in retrlines
    with self.transfercmd(cmd) as conn, \
         ^^^^^^^^^^^^^^^^^^^^^
  File "C:\Users\joser\.pyenv\pyenv-win\versions\3.12.7\Lib\ftplib.py", line 393, in transfercmd
    return self.ntransfercmd(cmd, rest)[0]
           ^^^^^^^^^^^^^^^^^^^^^^^^^^^^
  File "C:\Users\joser\.pyenv\pyenv-win\versions\3.12.7\Lib\ftplib.py", line 353, in ntransfercmd
    host, port = self.makepasv()
                 ^^^^^^^^^^^^^^^
  File "C:\Users\joser\.pyenv\pyenv-win\versions\3.12.7\Lib\ftplib.py", line 327, in makepasv
    untrusted_host, port = parse227(self.sendcmd('PASV'))
                           ^^^^^^^^^^^^^^^^^^^^^^^^^^^^^^
  File "C:\Users\joser\.pyenv\pyenv-win\versions\3.12.7\Lib\ftplib.py", line 817, in parse227
    raise error_reply(resp)
ftplib.error_reply: 200 Type set to A.
2025-08-18 17:18:03,932 - ERROR - src.transfer.ftp_manager - Falha no download do ficheiro: 'utf-8' codec can't decode byte 0xe9 in position 489: invalid continuation byte
Traceback (most recent call last):
  File "d:\Python\Sage\INP\transfer-files\src\transfer\ftp_manager.py", line 122, in download_file
    self.ftp.retrlines(f'RETR {remote_path}', f.write)
  File "C:\Users\joser\.pyenv\pyenv-win\versions\3.12.7\Lib\ftplib.py", line 462, in retrlines
    line = fp.readline(self.maxline + 1)
           ^^^^^^^^^^^^^^^^^^^^^^^^^^^^^
  File "C:\Users\joser\.pyenv\pyenv-win\versions\3.12.7\Lib\codecs.py", line 322, in decode
    (result, consumed) = self._buffer_decode(data, self.errors, final)
                         ^^^^^^^^^^^^^^^^^^^^^^^^^^^^^^^^^^^^^^^^^^^^^
UnicodeDecodeError: 'utf-8' codec can't decode byte 0xe9 in position 489: invalid continuation byte
2025-08-18 17:18:26,225 - ERROR - src.services.strategies - [1510] Falha no download de R2025081401.TXT.
2025-08-18 17:44:45,630 - ERROR - src.transfer.ftp_manager - Falha no download do ficheiro: 'utf-8' codec can't decode byte 0xe9 in position 489: invalid continuation byte
Traceback (most recent call last):
  File "d:\Python\Sage\INP\transfer-files\src\transfer\ftp_manager.py", line 121, in download_file
    self.ftp.retrlines(f'RETR {remote_path}', f.write)
  File "C:\Users\joser\.pyenv\pyenv-win\versions\3.12.7\Lib\ftplib.py", line 462, in retrlines
    line = fp.readline(self.maxline + 1)
           ^^^^^^^^^^^^^^^^^^^^^^^^^^^^^
  File "C:\Users\joser\.pyenv\pyenv-win\versions\3.12.7\Lib\codecs.py", line 322, in decode
    (result, consumed) = self._buffer_decode(data, self.errors, final)
                         ^^^^^^^^^^^^^^^^^^^^^^^^^^^^^^^^^^^^^^^^^^^^^
UnicodeDecodeError: 'utf-8' codec can't decode byte 0xe9 in position 489: invalid continuation byte
